Workbook

Sheet Mudança de Endereço 
N1: R$100,00
N2: R$70,00
N3: RENATA
D4: DATA: | E4: 45667 | N4: KAROLAYNE
D5: VALIDADO POR: | E5: HIAGO | H5: VALOR DA MUDANÇA: | I5: R$100,00 | N5: VICTOR HUGO
B6: VALIDAÇÕES | D6: TIPO DE SERVIÇO | H6: ATENDENTE: | N6: HIAGO
D7: NOME CLIENTE: | E7: ISABELLA SANTOS PAULA | H7: DATA AGENDAMENTO: | I7: =VLOOKUP($E$7,'base de dados'!$C:$I,4,0) -> 46176 | K7: HORA | L7: DIA | N7: IZABELA
B8: CONFERIR ORDEM DE SERVIÇO | D8: TELEFONE CLIENTE: | E8: =VLOOKUP($E$7,'base de dados'!$C:$S,3,0) -> 3499232699 | H8: HORA AGENDAMENTO: | I8: =VLOOKUP($E$7,'base de dados'!$C:$I,6,0) -> 0.41666667 | K8: =NOW() -> 46192.688 | L8: =TODAY() -> 46192 | N8: VITOR SILVA
B9: CONFERIR PROTOCOLO | D9: NOVO ENDEREÇO: | H9: FORMA DE PAGAMENTO: | I9: =VLOOKUP($E$7,'base de dados'!$C:$I,7,0) -> PIX
B10: CONFERIR SE ENDEREÇO NA ORDEM DE SERVIÇO E CADASTRO FORAM ALTERADOS | D10: =VLOOKUP($E$7,'base de dados'!$C:$J,8,0) -> ENDEREÇO NOVO: RUA JOSÉ VICENTE DA SILVA, 82 COMPLEMENTO: CASA UNICA CEP: 38425612 BAIRRO: SHOPPING PARK | H10: QUEM ACOMPANHA? | N10: MUD END
B11: CONFERIR EM PESSOAS E EMPRESAS SE POSSUI OUTRA INSTALAÇÃO ATIVA NO MESMO ENDEREÇO | H11: NOME: | I11: =VLOOKUP($E$7,'base de dados'!$C:$S,13,0) -> BERNADETE SANTOS PAULA (AVO) | N11: MUD END + ALT PLAN
B12: CONFERIR FINANCEIRO | H12: TELEFONE: | I12: =VLOOKUP($E$7,'base de dados'!$C:$S,14,0) -> 3499232699
B13: CONFERIR SE O CLIENTE TEM OU NÃO FIDELIDADE (SE NÃO TIVER, É RESPONSABILIDADE DO ATENDENTE OFERTAR E TER INFORMAÇÃO NO PROTOCOLO) | H13: OBSERVAÇÕES | N13: CARTÃO
B14: CASO SEJA COM ALTERAÇÃO DE PLANO: VERIFICAR NOVO PLANO E ROTEADOR, SE FOR PARA TROCAR EQUIPAMENTO PRECISA ESTAR NA O.S/PROTOCOLO E AGENDA EXCEL – ALTERAR OU ENVIAR PARA FINANCEIRO | D14: EQUIPAMENTO: | E14: =VLOOKUP($E$7,'base de dados'!$C:$K,9,0) -> <b>ONT = ONT TP LINK 230 // CONECTOR = VERDE.</b> | H14: =VLOOKUP($E$7,'base de dados'!$C:$S,2,0) -> VALIDAÇÃO OK | N14: DINHEIRO
B15: CONFERIR SE O “TIPO DE O.S” ESTÁ CORRETO | D15: TEXTO PROTOCOLO CONTATO FEITO: | E15: acompanhamento titular | N15: PIX
B16: CASO O CLIENTE TENHA SIDO INSTALADO COM MENOS DE 90 DIAS, PRECISA TER AUTORIZAÇÃO DO HIAGO/DEIVIT | D16: =CONCATENATE("TÉC. ",$E$5," ENTREI EM CONTATO COM ",$E$7," (",$E$8,") DIA ",TEXT(TODAY(),"DD/MM")," ÀS ",TEXT(NOW(),"HH:MM")," HORAS POR LIGAÇÃO . CONFIRMEI OS DADOS ABAIXO: ",$D$10," TAXA A SER PAGA NO MOMENTO DA INSTALAÇÃO DE ",$I$5," NO ",$I$9," E RESSALTEI QUE OS EQUIPAMENTOS DE INTERNET DEVEM SER LEVADOS PARA O NOVO ENDEREÇO, ONU, ROTEADOR OU ONT + (FONTES DE ENERGIA). ",$E$7," VAI ACOMPANHAR A VISITA. CONFIRMADO PARA DIA ",TEXT($I$7,"DD/MM")," ÁS ",TEXT($I$8,"HH:MM")," HORAS.") -> TÉC. HIAGO ENTREI EM CONTATO COM ISABELLA SANTOS PAULA (3499232699) DIA 19/06 ÀS 16:31 HORAS POR LIGAÇÃO . CONFIRMEI OS DADOS ABAIXO: ENDEREÇO NOVO: RUA JOSÉ VICENTE DA SILVA, 82 COMPLEMENTO: CASA UNICA CEP: 38425612 BAIRRO: SHOPPING PARK TAXA A SER PAGA NO MOMENTO DA INSTALAÇÃO DE R$100,00 NO PIX E RESSALTEI QUE OS EQUIPAMENTOS DE INTERNET DEVEM SER LEVADOS PARA O NOVO ENDEREÇO, ONU, ROTEADOR OU ONT + (FONTES DE ENERGIA). ISABELLA SANTOS PAULA VAI ACOMPANHAR A VISITA. CONFIRMADO PARA DIA 03/06 ÁS 10:00 HORAS. | H16: TEXTO PROTOCOLO SEM CONTATO: | N16: MENSALIDADE VINCENDA
B17: **ANTECIPAÇÕES** - VALIDAR DADOS NA LIGAÇÃO - ENVIAR NO GRUPO "TREINAMENTO" - INFORMAR QUE SE SURGIR VAGA QUE ENTRAREMOS EM CONTATO PARA - INFORMAR E VERIFICAR DISPONIBILIDADE DO CLIENTE | H17: =CONCATENATE("TÉC. ",$E$5," TENTEI CONTATO COM ",E7," POR LIGAÇÃO (",E8,") DIA ",TEXT(TODAY(),"DD/MM")," ÀS ",TEXT(K8,"HH:MM"),"HORAS, TELEFONE NÃO ATENDE. ENVIEI MENSAGEM WHATSAPP AGUARDANDO RETORNO.") -> TÉC. HIAGO TENTEI CONTATO COM ISABELLA SANTOS PAULA POR LIGAÇÃO (3499232699) DIA 19/06 ÀS 16:31HORAS, TELEFONE NÃO ATENDE. ENVIEI MENSAGEM WHATSAPP AGUARDANDO RETORNO. | N17: ISENTO
N19: 0.35416667
N20: 0.4375
N21: 0.5625
B22: - VERIFICAR SE MUDANÇA ESTÁ SAINDO DE RESIDENCIAL PARA COMERCIO, OU VICE VERSA E SE POSSUI AUTORIZAÇÃO PARA PROSSEGUIR. | N22: 0.64583333
N23: A PARTIR DAS 11:00
B28: ALTERAÇÃO DE PLANO? | D28: TEXTO PROTOCOLO CONTATO FEITO: | E28: (acompanhamento terceiros
B29: =VLOOKUP($E$7,'base de dados'!$C:$M,11,0) -> - | D29: =CONCATENATE("TÉC. ",$E$5," ENTREI EM CONTATO COM ",$E$7," (",$E$8,") DIA ",TEXT(TODAY(),"DD/MM")," ÀS ",TEXT(NOW(),"HH:MM")," HORAS POR LIGAÇÃO. CONFIRMEI OS DADOS ABAIXO: ",$D$10," TAXA A SER PAGA NO MOMENTO DA INSTALAÇÃO DE R$100,00 NO ",$I$9," E RESSALTEI QUE OS EQUIPAMENTOS DE INTERNET DEVEM SER LEVADOS PARA O NOVO ENDEREÇO, ONU, ROTEADOR OU ONT + (FONTES DE ENERGIA).",$E$7," AUTORIZA ",$I$11, " (",$I$12,") ACOMPANHAR A VISITA. CONFIRMADO PARA DIA ",TEXT($I$7,"DD/MM")," ÁS ",TEXT($I$8,"HH:MM")," HORAS.") -> TÉC. HIAGO ENTREI EM CONTATO COM ISABELLA SANTOS PAULA (3499232699) DIA 19/06 ÀS 16:31 HORAS POR LIGAÇÃO. CONFIRMEI OS DADOS ABAIXO: ENDEREÇO NOVO: RUA JOSÉ VICENTE DA SILVA, 82 COMPLEMENTO: CASA UNICA CEP: 38425612 BAIRRO: SHOPPING PARK TAXA A SER PAGA NO MOMENTO DA INSTALAÇÃO DE R$100,00 NO PIX E RESSALTEI QUE OS EQUIPAMENTOS DE INTERNET DEVEM SER LEVADOS PARA O NOVO ENDEREÇO, ONU, ROTEADOR OU ONT + (FONTES DE ENERGIA).ISABELLA SANTOS PAULA AUTORIZA BERNADETE SANTOS PAULA (AVO) (3499232699) ACOMPANHAR A VISITA. CONFIRMADO PARA DIA 03/06 ÁS 10:00 HORAS.

Sheet base de dados
A1: TEXTO AGENDA | B1: TIPO DE MUDANÇA | C1: NOME | D1: CONFERENCIA SISTEMA | E1: TELEFONE | F1: DATA MUDANÇA | G1: DIA DA SEMANA | H1: HORARIO MUDANÇA | I1: FORMA DE PAGAMENTO | J1: NOVO ENDEREÇO | K1: EQUIPAMENTO | L1: ALTERAÇÃO DE PLANO | M1: PLANO ESCOLHIDO | N1: TITULAR ACOMPANHA? | O1: NOME + GRAU DE PARENTESCO | P1: TELEFONE TERCEIRO | Q1: TEXTO COMPROVANTE DE ENDEREÇO | R1: CONFERENCIA END, COMPROVANTE | S1: PRAZO VALIDAÇÃO OK? | Y1: MUD END + ALT PLAN
A2: 10/04 MUD END CARLOS AUGUSTO RODRIGUES DE MATTOS PROT:2603.33782 CARTAO (GABRIEL M.) - LAGOINHA | B2: MUD END | D2: VALIDADO | E2: 34988647760 | F2: 46032 | G2: =PROPER(TEXT(F2,"DDD")) -> Sáb | H2: 0.33333333 | I2: CARTÃO | J2: ENDEREÇO NOVO: RUA BENTO DE FARIA, 80 COMPLEMENTO: CASA UNICA CEP: 38408514 BAIRRO: LAGOINHA | K2: <b>ONU = DATA // CONECTOR = VERDE.</b> | L2: =IF(B2="MUD END","NÃO","SIM") -> NÃO | N2: SIM | O2: - | P2: - | Q2: COMPROVANTE DE ENDEREÇO (CEMIG) EM ANEXO NOME NO COMPROVANTE: MARIA HELENA VASCONCELOS DE OLIVEIRA (DISSE SER PRIMA DO ASSINANTE.) | S2: =IF(F2<TODAY(),"EXECUTADA",IF(F2=TODAY(),"EM EXECUÇÃO",IF(F2=TODAY()+1,"VALIDAR HOJE",IF(F2>TODAY()+1,"VALIDAR DEPOIS","-")))) -> EXECUTADA
A3: MUD END ENEIAS RODRIGUES DE SOUZA (NOVO VISUAL SERVICOS GRAFICA) PROT:2603.1107 PIX (HALYSON) - OSVALDO REZENDE **(POSSUI WI-FI EXTEND)** *PENDENTE COMPROVANTE PAGAMENTO E ENDEREÇO* | B3: MUD END | E3: 34992322706 | F3: 46114 | G3: =PROPER(TEXT(F3,"DDD")) -> Qui | H3: 0.33333333 | I3: PIX | J3: ENDEREÇO NOVO: RUA ANTÔNIO THOMAZ DE REZENDE, 201 COMPLEMENTO: SALA 5 REFERÊNCIA: GALPÃO CEP: 38400487 BAIRRO: OSVALDO REZENDE | K3: <b>ONT = ONT TP LINK 530 // CONECTOR = VERDE.</b> | L3: =IF(B3="MUD END","NÃO","SIM") -> NÃO | M3: - | N3: sim | S3: =IF(F3<TODAY(),"EXECUTADA",IF(F3=TODAY(),"EM EXECUÇÃO",IF(F3=TODAY()+1,"VALIDAR HOJE",IF(F3>TODAY()+1,"VALIDAR DEPOIS","-")))) -> EXECUTADA
A4: MUD END + ALT PLANO LUCAS FERREIRA GOMES PROT:2603.34716 ISENTO (JHONATAN) - DANIEL FONSECA | B4: MUD END + ALT PLAN | D4: VALIDAÇÃO OK ENVIAR AO CADASTRO selfie pendente de documento | E4: 34991631067 | F4: 46114 | G4: =PROPER(TEXT(F4,"DDD")) -> Qui | H4: 0.33333333 | I4: ISENTO | J4: ENDEREÇO NOVO: RUA VARGINHA, 1155 COMPLEMENTO: COND. MARANATA, APT 203 CEP: 38400322 BAIRRO: DANIEL FONSECA | K4: . <b>ONT = ONT ZTE // CONECTOR = VERDE.</b> | L4: =IF(B4="MUD END","NÃO","SIM") -> SIM | M4: PLANO ATUAL: 1000 MEGA/99,90 CONTRATADO EM 07/2025 COM FIDELIDADE DE 12 MESES. ROTEADOR: ONT ZTE F 670-L PLANO SOLICITADO: 1 GIGA (1.000 MEGA) R$99,90. BENEFÍCIOS: ACESSO GRATUITO AO APP MZTV (CDNTV+) + VOD | N4: NÃO | O4: DOUGLAS FERNANDES BORGES. (INQUILINO) | P4: 64 9328-2617 | Q4: COMPROVANTE DE ENDEREÇO (CONTRATO DE LOCAÇÃO) EM ANEXO NOME NO COMPROVANTE: DOUGLAS FERNANDES BORGES (INQUILINO) | R4: MK END: N/C ___________________________ MK NOMES: -> SOCRATES RODRIGUES QUEIROZ - CPF: 052.678.796-14 - LOCADOR DO IMÓVEL - CLIENTE ATIVO NO ENDEREÇO: RUA SEBASTIAO DE FREITAS, 287. ADIMPLENTE COM EMPRESA; -> POLIANA EVANGELISTA SILVA - CPF: 059.825.136-79 - LOCATÁRIA DO IMÓVEL - N/C ; -> DOUGLAS FERNANDES BORGES - CPF: 056.809.281-26 - LOCATÁRIO DO IMÓVEL - N/C ; -> LUCAS FERREIRA GOMES - CPF: 065.584.586-08 - CLIENTE ATIVO E ADIMPLENTE COM A EMPRESA. | S4: =IF(F4<TODAY(),"EXECUTADA",IF(F4=TODAY(),"EM EXECUÇÃO",IF(F4=TODAY()+1,"VALIDAR HOJE",IF(F4>TODAY()+1,"VALIDAR DEPOIS","-")))) -> EXECUTADA
A5: MUD END + ALT PLANO EDUARDO APARECIDO DA SILVA PROT:2603.34636 ISENTO (JOSÉ Jr) - JARDIM BOTÂNICO **PRÉDIO COM PRUMADA** // *TROCA DE EQUIPAMENTO* | B5: MUD END + ALT PLAN | D5: VALIDAÇÃO OK ENVIAR AO CADASTRO | E5: 34998684694 | F5: 46114 | G5: =PROPER(TEXT(F5,"DDD")) -> Qui | H5: 0.41666667 | I5: ISENTO | J5: ENDEREÇO NOVO: AVENIDA VEREADOR CARLITO CORDEIRO, 1895 COMPLEMENTO: CONDOMINIO RESIDENCIAL PARK KARAIBA BL-A APT 109 CEP: 38410665 BAIRRO: JARDIM BOTÂNICO | K5: <b>ONU = DATA // CONECTOR = VERDE.</b> | L5: =IF(B5="MUD END","NÃO","SIM") -> SIM | M5: PLANO ATUAL: 500 MEGA/79,90 CONTRATADO EM 04/2024 COM FIDELIDADE DE 12 MESES. ROTEADOR: GREATEK PLANO OFERTADO: 600 MEGA/79,90. BENEFÍCIOS: ACESSO GRATUITO AO APP MZTV (CDNTV+) | N5: SIM | O5: - | P5: - | Q5: COMPROVANTE DE ENDEREÇO (TAXA DE CONDOMINIO ) EM ANEXO NOME NO COMPROVANTE: ALINE CAREN CARDOSO (CLIENTE DIZ QUE É SUA ESPOSA) | R5: MK END:N/C MK NOMES: ALINE CAREN CARDOSO CPF:***.619.116-**(CLIENTE DIZ QUE É SUA ESPOSA)N/C SCHWARTZ COBRE LTDA CNPJ:18.450.750/0001-20(EMPRESA RESPONSÁVEL PELO RECEBIMENTO DOS VALORES DA TAXA DE CONDOMÍNIO)N/C | S5: =IF(F5<TODAY(),"EXECUTADA",IF(F5=TODAY(),"EM EXECUÇÃO",IF(F5=TODAY()+1,"VALIDAR HOJE",IF(F5>TODAY()+1,"VALIDAR DEPOIS","-")))) -> EXECUTADA
A6: MUD END + ALT PLANO JULIA GABRIELA MARIA DORNELES PROT:2603.35607 ISENTO (BRUNA) - LARANJEIRAS // *ASSINATURA PEND* | B6: MUD END + ALT PLAN | D6: VALIDAÇÃO OK ENVIAR AO CADASTRO PENDENTE ASSINATURA DO CONTRATO | E6: 34984190334 | F6: 46114 | G6: =PROPER(TEXT(F6,"DDD")) -> Qui | H6: 0.54166667 | I6: ISENTO | J6: ENDEREÇO NOVO: RUA DAS DIRETAS, 165 COMPLEMENTO: CASA 2 CEP: 38410492 BAIRRO: LARANJEIRAS | K6: <b>ONT = ONT TP LINK 530 // CONECTOR = VERDE.</b> | L6: =IF(B6="MUD END","NÃO","SIM") -> SIM | M6: PLANO ATUAL: 1000 MEGA/99,90 CONTRATADO EM 05/25 COM FIDELIDADE DE 12 MESES. ROTEADOR: ONT TP-LINK X530 PLANO OFERTADO: 1 GIGA (1.000 MEGA) R$99,90. BENEFÍCIOS: ACESSO GRATUITO AO APP MZTV (CDNTV+) + VOD | N6: SIM | O6: - | P6: - | Q6: COMPROVANTE DE ENDEREÇO (CEMIG) EM ANEXO NOME NO COMPROVANTE: VINICIUS RIBEIRO SANTOS (DIZ SER ANTIGO INQUILINO) | R6: MK END: N/C MK NOMES: VINICIUS RIBEIRO SANTOS (ANTIGO INQUILINO): HAVIA REALIZADO PEDIDO DE INSTALAÇÃO EM 17/03/2023, PORÉM, A FICHA FOI REPROVADA DEVIDO AO SCORE BAIXO E RESTRIÇÕES. | S6: =IF(F6<TODAY(),"EXECUTADA",IF(F6=TODAY(),"EM EXECUÇÃO",IF(F6=TODAY()+1,"VALIDAR HOJE",IF(F6>TODAY()+1,"VALIDAR DEPOIS","-")))) -> EXECUTADA
A7: MUD END + ALT PLANO DENISE DE FREITAS PROT:2603.22413 ISENTO (ANDREZA) - JARDIM DAS PALMEIRAS // *LIGAR QUANDO ESTIVER A CAMINHO* | B7: MUD END + ALT PLAN | D7: VALIDAÇÃO OK ENVIAR AO CADASTRO | E7: (34) 99987-1906 | F7: 46114 | G7: =PROPER(TEXT(F7,"DDD")) -> Qui | H7: 0.54166667 | I7: ISENTO | J7: ENDEREÇO NOVO: RUA DO TOPÓGRAFO, 80 COMPLEMENTO: CASA ÚNICA CEP: 38412280 BAIRRO: JARDIM DAS PALMEIRAS | K7: <b>ONT = ONT TP LINK 230 // CONECTOR = VERDE.</b> | L7: =IF(B7="MUD END","NÃO","SIM") -> SIM | M7: PLANO ATUAL: 600 MEGA/79,90 CONTRATADO EM 07/2025 COM FIDELIDADE DE 12 MESES. ROTEADOR: ONT TP-LINK XC230 PLANO OFERTADO: 600 MEGA/79,90. BENEFÍCIOS: ACESSO GRATUITO AO APP MZTV (CDNTV+) | N7: SIM | O7: - | P7: - | Q7: COMPROVANTE DE ENDEREÇO (CEMIG) EM ANEXO NOME NO COMPROVANTE: DENISE DE FREITAS AMARAL (ASSINANTE) | R7: MK END: -> AMARILDO ROBERTO SILVA (EX ESPOSO DA ASSINANTE) - CPF 739.538.576-49: CONEXÃO ATIVA DESDE 10/2020 E ADIMPLENTE COM A EMPRESA. >>> ESTÁ COM MUDANÇA DE ENDEREÇO AGENDADA PARA 01/04. ________________________________________ MK NOMES: -> DENISE DE FREITAS AMARAL - CPF 059.756.676-31: ASSINANTE DA CONEXÃO. | S7: =IF(F7<TODAY(),"EXECUTADA",IF(F7=TODAY(),"EM EXECUÇÃO",IF(F7=TODAY()+1,"VALIDAR HOJE",IF(F7>TODAY()+1,"VALIDAR DEPOIS","-")))) -> EXECUTADA
A8: MUD END + ALT PLANO BRUNA DA SILVA GUMERATO PROT:2603.32071 ISENTO (RONALD) - LOTEAMENTO RESIDENCIAL PEQUIS // *CLIENTE CONTRATOU PLANO WI-FI EXTEND* | B8: MUD END + ALT PLAN | D8: OS ERRADA CASO SEJA APROVADO O EXTEND PARA CASA FRENTE DA MÃE .. SERÁ NECESSÁRIO GERAR 2 OS | E8: 34992354684 | F8: 46114 | G8: =PROPER(TEXT(F8,"DDD")) -> Qui | H8: 0.54166667 | I8: ISENTO | J8: ENDEREÇO NOVO: RUA DO AZULÃO, 176 COMPLEMENTO: CASA FUNDOS CEP: 38421040 BAIRRO: LOTEAMENTO RESIDENCIAL PEQUIS | K8: <b>ONT = ONT TP LINK 230 // CONECTOR = VERDE.</b> | L8: =IF(B8="MUD END","NÃO","SIM") -> SIM | M8: PLANO ATUAL: 600 MEGA/79,90 CONTRATADO EM 01/2025 COM FIDELIDADE DE 12 MESES. ROTEADOR: ONT TP-LINK XC230 PLANO OFERTADO: 1 GIGA (1.000 MEGA); + WI-FI EXTEND (ROTEADOR ADICIONAL) MENSALIDADE: R$134,90; EQUIPAMENTOS EMPRESTADOS EM REGIME DE COMODATO + INSTALAÇÃO/ATIVAÇÃO GRÁTIS; BENEFÍCIOS: ACESSO GRATUITO AO APP MZTV (CDNTV+) + VOD | N8: SIM | O8: - | P8: - | Q8: COMPROVANTE DE ENDEREÇO (CEMIG) EM ANEXO NOME NO COMPROVANTE: ANA PAULA DA SILVA (MAE DE BRUNA) | S8: =IF(F8<TODAY(),"EXECUTADA",IF(F8=TODAY(),"EM EXECUÇÃO",IF(F8=TODAY()+1,"VALIDAR HOJE",IF(F8>TODAY()+1,"VALIDAR DEPOIS","-")))) -> EXECUTADA
A9: MUD END + ALT PLANO RAFFAEL SOUZA PIRES PROT:2603.35843 ISENTO (VICTOR H.) - OSVALDO REZENDE **PRÉDIO SEM PRUMADA - ENVIAR TÉCNICO DUPLADO** // *TROCA DE EQUIPAMENTO* | B9: MUD END + ALT PLAN | D9: VALIDAÇÃO OK ENVIAR AO CADASTRO pendente selfie | E9: 34988066015 | F9: 46114 | G9: =PROPER(TEXT(F9,"DDD")) -> Qui | H9: 0.625 | I9: ISENTO | J9: ENDEREÇO NOVO: RUA TAPUIRAMA, 447 COMPLEMENTO: APTO 301 CEP: 38400436 BAIRRO: OSVALDO REZENDE | K9: <b>ONU = DATA // CONECTOR = VERDE.</b> | L9: =IF(B9="MUD END","NÃO","SIM") -> SIM | M9: PLANO ATUAL: 400 MEGA/79,90 CONTRATADO EM 01/2023 COM FIDELIDADE DE 12 MESES. ROTEADOR: GREATEK PLANO OFERTADO: 600 MEGA/79,90. BENEFÍCIOS: ACESSO GRATUITO AO APP MZTV (CDNTV+) | N9: SIM | O9: - | P9: - | Q9: COMPROVANTE DE ENDEREÇO (CONTRATO DE LOCAÇÃO) EM ANEXO NOME NO COMPROVANTE: RAFFAEL SOUZA PIRES (ASSINANTE) | R9: MK NOMES: RAFFAEL SOUZA PIRES CPF: 108.562.846-96 (LOCATÁRIO) ASSINANTE - CONTRATOU EM 01/2023 CONEXÃO ATIVA E ADIMPLENTE DANIELLY PIRES VILELA CPF: 064.549.751-77 (LOCATÁRIA) CONEXÃO CANCELADA EM 04/2024 - QUITOU OS DÉBITOS COM A EMPRESA APÓS ACORDO SUELY FRANCISCA DE SOUZA CPF: 578.091.786-87 (FIADORA) - N/C DIJANIRA FRANCISCA DE OLIVEIRA CPF: 460.756.906-20 (FIADORA) - N/C SANTA FELICIA HOLDING PATRIMONIAL LTDA CNPJ: 22.579.858/0001-95 (LOCADORA) - N/C RGV NEGÓCIOS IMOBILIÁRIOS LTDA CNPJ: 17.808.663/0001-30 (ADMINISTRADORA) - N/C MK END: N/C | S9: =IF(F9<TODAY(),"EXECUTADA",IF(F9=TODAY(),"EM EXECUÇÃO",IF(F9=TODAY()+1,"VALIDAR HOJE",IF(F9>TODAY()+1,"VALIDAR DEPOIS","-")))) -> EXECUTADA
A10: MUD END THIAGO WILKER MELO MIRANDA PROT:2603.35688 CARTAO (RONALD) - TUBALINA **PRÉDIO COM PRUMADA** | B10: MUD END | D10: VALIDAÇÃO OK ENVIAR AO CADASTRO | E10: 34991455433 | F10: 46114 | G10: =PROPER(TEXT(F10,"DDD")) -> Qui | H10: 0.625 | I10: CARTÃO | J10: ENDEREÇO NOVO: RUA VOLUNTÁRIOS DA PÁTRIA, 566 COMPLEMENTO: APT. 201 CEP: 38412072 BAIRRO: TUBALINA | K10: <b>ONT = ONT TP LINK 530 // CONECTOR = VERDE.</b> | L10: =IF(B10="MUD END","NÃO","SIM") -> NÃO | M10: - | N10: SIM | O10: - | P10: - | Q10: COMPROVANTE DE ENDEREÇO (DMAE) EM ANEXO NOME NO COMPROVANTE: THIAGO WILKER MELO MIRANDA (ASSINANTE) | R10: MK END; N/C MK NOME; THIAGO WILKER MELO MIRANDA 015.929.236-07 (ASSINANTE) CONEXÃO ATIVA E CLIENTE ADIMPLENTE | S10: =IF(F10<TODAY(),"EXECUTADA",IF(F10=TODAY(),"EM EXECUÇÃO",IF(F10=TODAY()+1,"VALIDAR HOJE",IF(F10>TODAY()+1,"VALIDAR DEPOIS","-")))) -> EXECUTADA
A11: MUD END RANGEL DE JESUS SOUSA PROT:2603.35872 PIX (VICTOR H.) - GUARANI | B11: MUD END | D11: VALIDAÇÃO OK ENVIAR AO CADASTRO | E11: 34998086440 | F11: 46114 | G11: =PROPER(TEXT(F11,"DDD")) -> Qui | H11: 0.70833333 | I11: PIX | J11: ENDEREÇO NOVO: RUA DA MAZURKA, 582 COMPLEMENTO: CASA FRENTE CEP: 38415417 BAIRRO: GUARANI | K11: <b>ONU = DATA // CONECTOR = VERDE.</b> | L11: =IF(B11="MUD END","NÃO","SIM") -> NÃO | M11: - | N11: SIM | O11: - | P11: - | Q11: COMPROVANTE DE ENDEREÇO (CEMIG) EM ANEXO NOME NO COMPROVANTE: JORCELINO PEREIRA MACEDO FILHO (DISSE SER PROPRIETÁRIO DO IMÓVEL ) | R11: MK END MARIA GLORIA MACEDO (CASA FUNDOS) CANCELOU EM 04/2024, NÃO POSSUI DÉBITOS COM A EMPRESA MK NOMES JORCELINO PEREIRA MACEDO FILHO (DISSE SER PROPRIETÁRIO DO IMÓVEL) - N/C | S11: =IF(F11<TODAY(),"EXECUTADA",IF(F11=TODAY(),"EM EXECUÇÃO",IF(F11=TODAY()+1,"VALIDAR HOJE",IF(F11>TODAY()+1,"VALIDAR DEPOIS","-")))) -> EXECUTADA
A12: MUD END SUIANI TERTO DA SILVA (ESCRITORIO DE ADVOCACIA UNID02) PROT:2603.34007 PIX (ANDREZA) - LUIZOTE DE FREITAS // *ANÁLISE DE 90 DIAS* | B12: MUD END | D12: JA VALIDADO PELO CADASTRO | E12: 64996012416 | F12: 46114 | G12: =PROPER(TEXT(F12,"DDD")) -> Qui | H12: 0.70833333 | I12: PIX | J12: ENDEREÇO NOVO: RUA MATHEUS VAZ, 420 COMPLEMENTO: COMÉRCIO FRENTE CEP: 38414308 BAIRRO: LUIZOTE DE FREITAS | K12: <b>ONT = ONT TP LINK 530 // CONECTOR = VERDE.</b> | L12: =IF(B12="MUD END","NÃO","SIM") -> NÃO | M12: - | N12: SIM | O12: DALILA (ASSESSORA JURÍDICA DE SUIANI) | P12: 64999808642 | Q12: COMPROVANTE DE ENDEREÇO (CONTRATO DE LOCAÇÃO) EM ANEXO NOME NO COMPROVANTE: SUIANI TERTO DA SILVA (ASSINANTE) | R12: MK END: N/C ________________________________________ MK NOMES: -> ROSANGELA RAMILA DE SOUZA (LOCADORA) - CPF 539.306.656-20: N/C -> DELTA IMÓVEIS E ADMINISTRAÇÃO LTDA (PROCURADORA) - CNPJ 23.976.590/0001-98: N/C -> FRANCIS HEME CESAR PEREIRA (REPRESENTANTE) - CPF 086.429.536-75: N/C -> SUIANI TERTO DA SILVA SOCIEDADE INDIVIDUAL DE ADVOCACIA / SUIANI TERTO DA SILVA (LOCATÁRIA/FIADORA) - CNPJ 51.678.451/0001-13 // 032.711.821-08: ASSINANTE DA CONEXÃO. :. POSSUI OUTRAS DUAS CONEXÕES ATIVAS E ADIMPLENTE COM A EMPRESA.: ::. POSSUI UMA SOLICITAÇÃO DE ADESÃO DO ESCRITÓRIO EM SEU CPF APROVADA PARA O CNPJ .:: -> VALERIA CRISTINA FERREIRA DE CARVALHO (TESTEMUNHA): N/C -> RHAYANNE MYCHELLE INÁCIO DE PAULA (TESTEMUNHA): CONEXÃO ATIVA DESDE 11/2025 E ADIMPLENTE COM A EMPRESA. -> DALILA TERTO (ASSESSORA JURÍDICA): N/C | S12: =IF(F12<TODAY(),"EXECUTADA",IF(F12=TODAY(),"EM EXECUÇÃO",IF(F12=TODAY()+1,"VALIDAR HOJE",IF(F12>TODAY()+1,"VALIDAR DEPOIS","-")))) -> EXECUTADA
A13: MUD END + ALT PLANO LUCIEUDA GONCALVES DO NASCIMENTO PROT:2603.34925 ISENTO (LUIS) - GUARANI // | B13: MUD END + ALT PLAN | D13: VALIDAÇÃO OK ENVIAR AO CADASTRO pendente selfie | E13: 34991777444 | F13: 46115 | G13: =PROPER(TEXT(F13,"DDD")) -> Sex | H13: 0.41666667 | I13: ISENTO | J13: ENDEREÇO NOVO: RUA DO BALLET, 784 COMPLEMENTO: CASA ÚNICA CEP: 38415408 BAIRRO: GUARANI | K13: <b>ONU = DATA // CONECTOR = VERDE.</b> | L13: =IF(B13="MUD END","NÃO","SIM") -> SIM | M13: PLANO ATUAL: 250 MEGA/69,90 CONTRATADO EM 07/2023 COM FIDELIDADE DE 12 MESES. ROTEADOR: GREATEK PLANO OFERTADO: 300 MEGA/69,90. BENEFÍCIOS: ACESSO GRATUITO AO APP MZTV (CDNTV+) | N13: SIM | O13: - | P13: - | Q13: COMPROVANTE DE ENDEREÇO (CONTRATO DE LOCAÇÃO) EM ANEXO NOME NO COMPROVANTE: ANGELICA GONCALVES PEREIRA (LUCIEUDA ALEGA SER SUA FILHA) | R13: MK END: N/C MK NOMES: - ALESSANDRA DE MELO BELELLI - LOCADORA - N/C - ANGELICA GONÇALVES PEREIRA - CPF 614.285.203-76 - LOCATÁRIA (FILHA) - FICHA CADASTRAL REALIZADA EM 26/07/2023 ONDE FOI NEGADA EM SEU NOME E APROVADO NO NOME DA MÃE LUCIEUDA GONCALVES DO NASCIMENTO. INSTALDO EM RUA AGENOR BORGES, 280 - APTO 01. - LUCIEUDA GONCALVES DO NASCIMENTO - CPF 039.937.403-51 - ASSINANTE - CLIENTE ATIVA E ADIMPLENTE COM A EMPRESA. | S13: =IF(F13<TODAY(),"EXECUTADA",IF(F13=TODAY(),"EM EXECUÇÃO",IF(F13=TODAY()+1,"VALIDAR HOJE",IF(F13>TODAY()+1,"VALIDAR DEPOIS","-")))) -> EXECUTADA
A14: MUD END FABIANA GONÇALVES PROT:2603.35547 DINHEIRO (JHONATAN) - PAMPULHA | B14: MUD END | D14: VALIDAÇÃO OK ENVIAR AO CADASTRO | E14: 34991006033 | F14: 46115 | G14: =PROPER(TEXT(F14,"DDD")) -> Sex | H14: APOS AS 11:00 | I14: DINHEIRO | J14: ENDEREÇO NOVO: RUA OLIVEIRA LIMA, 959 COMPLEMENTO: CASA UNICA CEP: 38408650 BAIRRO: PAMPULHA | K14: <b>ONT = ONT TP LINK 220 // CONECTOR = VERDE.</b> | L14: =IF(B14="MUD END","NÃO","SIM") -> NÃO | M14: - | N14: SIM | O14: RENNER (ESPOSO DE FABIANA) | P14: 34991301190 | Q14: COMPROVANTE DE ENDEREÇO (CONTRATO DE LOCAÇÃO) EM ANEXO NOME NO COMPROVANTE: FABIANA GONÇALVES (ASSINANTE) | R14: -> FABIO HENRIQUE ALVEZ - SOLICITAÇÃO DE ADESÃO REPROVADA EM 02/02/2022 :. CONSTA NO CADASTRO -> RUA OLIVEIRA LIMA 959 - PAMPULHA (CASA-1) PORÉM NÃO IDENTIFIQUEI DUAS CASA COM O NUMERO 959. (EVIDÊNCIA EM ANEXO) ________________________________________________________________________________ MK NOME -> DERLY RENNER LONDRES CAMPOS (DISSE QUE É ESPOSO DA ASSINANTE): N/C -> FABIANA GONÇALVES (LOCADORA): ASSINANTE DA CONEXÃO -> SEBASTIÃO MANOELDA SILVA (LOCADOR): N/C | S14: =IF(F14<TODAY(),"EXECUTADA",IF(F14=TODAY(),"EM EXECUÇÃO",IF(F14=TODAY()+1,"VALIDAR HOJE",IF(F14>TODAY()+1,"VALIDAR DEPOIS","-")))) -> EXECUTADA
A15: MUD END CLAUDIONOR JOSE SILVA SANTOS PROT:2603.35845 PIX (VAGNER) - JARDIM EUROPA | B15: MUD END | D15: VALIDAÇÃO OK ENVIAR AO CADASTRO | E15: 34988827305 | F15: 46115 | G15: =PROPER(TEXT(F15,"DDD")) -> Sex | H15: APOS AS 13:00 | I15: PIX | J15: ENDEREÇO NOVO: RUA RIO SOLIMÕES, 1331 COMPLEMENTO: CASA UNICA CEP: 38414536 BAIRRO: JARDIM EUROPA | K15: <b>ONT = ONT TP LINK 530 // CONECTOR = VERDE.</b> | L15: =IF(B15="MUD END","NÃO","SIM") -> NÃO | M15: - | N15: SIM | O15: - | P15: - | Q15: COMPROVANTE DE ENDEREÇO (DMAE) EM ANEXO NOME NO COMPROVANTE: DOUGLAS NUNES MATOS (CLAUDIONOR ALEGAR SER O ANTIGO MORADOR) | R15: MK END: N/C MK NOME: DOUGLAS NUNES MATOS (CLAUDIONOR ALEGAR SER O ANTIGO MORADOR) - N/C | S15: =IF(F15<TODAY(),"EXECUTADA",IF(F15=TODAY(),"EM EXECUÇÃO",IF(F15=TODAY()+1,"VALIDAR HOJE",IF(F15>TODAY()+1,"VALIDAR DEPOIS","-")))) -> EXECUTADA
A16: MUD END GILMAR VIANNA SOARES PROT:2603.33901 CARTAO (ANDREZA) - PRESIDENTE ROOSEVELT // | B16: MUD END | D16: VALIDAÇÃO OK ENVIAR AO CADASTRO | E16: 34998971039 | F16: 46115 | G16: =PROPER(TEXT(F16,"DDD")) -> Sex | H16: APÓS AS 13:00 | I16: CARTÃO | J16: ENDEREÇO NOVO: RUA TUFI MAMERI, 305 COMPLEMENTO: CASA ÚNICA CEP: 38401034 BAIRRO: PRESIDENTE ROOSEVELT | K16: <b>ONT = ONT TP LINK 220 // CONECTOR = VERDE.</b> | L16: =IF(B16="MUD END","NÃO","SIM") -> NÃO | M16: - | N16: SIM | O16: - | P16: - | Q16: COMPROVANTE DE ENDEREÇO (CEMIG) EM ANEXO NOME NO COMPROVANTE: ROMILDA SOUZA SANTANA (DISSE QUE É A DONA DO IMÓVEL) | R16: MK END: N/C ________________________________________ MK NOMES: -> ROMILDA SOUZA SANTANA (DISSE QUE É A DONA DO IMÓVEL) - CPF 710.4**.***-**: N/C | S16: =IF(F16<TODAY(),"EXECUTADA",IF(F16=TODAY(),"EM EXECUÇÃO",IF(F16=TODAY()+1,"VALIDAR HOJE",IF(F16>TODAY()+1,"VALIDAR DEPOIS","-")))) -> EXECUTADA
A17: MUD END + ALT PLANO KATIUCIA SILVA SANTOS PROT:2603.32174 ISENTO (HALYSON) - JARDIM EUROPA // *03/04/2026 ÁS 08HS // | B17: MUD END + ALT PLAN | D17: VALIDAÇÃO OK ENVIAR AO CADASTRO PENDENTE ASSINATURA DE CONTRATO | E17: 84999800965 | F17: 46116 | G17: =PROPER(TEXT(F17,"DDD")) -> Sáb | H17: 0.33333333 | I17: ISENTO | J17: ENDEREÇO NOVO: RUA MANCHESTER, 85 COMPLEMENTO: CASA 01 CEP: 38414565 BAIRRO: JARDIM EUROPA | K17: <b>ONT = ONT ZTE // CONECTOR = VERDE.</b> | L17: =IF(B17="MUD END","NÃO","SIM") -> SIM | M17: PLANO ATUAL: 1000 MEGA/99,90 CONTRATADO EM 04/2024 COM FIDELIDADE DE 12 MESES. ROTEADOR: ONT ZTE F 670-L PLANO OFERTADO: 1 GIGA (1.000 MEGA) R$99,90. BENEFÍCIOS: ACESSO GRATUITO AO APP MZTV (CDNTV+) + VOD | N17: SIM | O17: JESSICA (CUNHADA DE KATIUCIA) | P17: 34998616817 | Q17: COMPROVANTE DE ENDEREÇO (CEMIG) EM ANEXO NOME NO COMPROVANTE: ALCINEIA MARQUES GUIMARAES TIBURCIO (DISSE QUE É A PROPRIETARIA DO IMOVÉL) | R17: MK END - SOFIA BARBOSA DE MORAIS: CONEXÃO CANCELADA SEM DÉBITOS - DANIELA PIRES VALADAO: PROCESSO DE ADESÃO CANCELADO (CLIENTE NÃO TEVE INTERESSE EM PAGAR TAXA DE INSTALAÇÃO) - ALCINEIA MARQUES GUIMARAES TIBURCIO (CASA 2): POSSUI CONEXÃO ATIVA COM PROTOCOLO (2603.22437) DE CANCELAMENTO EM ABERTO // FATURA 25/03 NO VALOR DE 79,90 EM ABERTO // MK NOMES - KATIUCIA SILVA SANTOS (ASSINANTE): POSSUI CONEXÃO ATIVA E ADIMPLENTE - ALCINEIA MARQUES GUIMARAES TIBURCIO (CASA 2): POSSUI CONEXÃO ATIVA COM PROTOCOLO (2603.22437) DE CANCELAMENTO EM ABERTO // FATURA 25/03 NO VALOR DE 79,90 EM ABERTO | S17: =IF(F17<TODAY(),"EXECUTADA",IF(F17=TODAY(),"EM EXECUÇÃO",IF(F17=TODAY()+1,"VALIDAR HOJE",IF(F17>TODAY()+1,"VALIDAR DEPOIS","-")))) -> EXECUTADA
A18: MUD END + ALT PLANO LETICIA BARBOSA DOS SANTOS PROT:2603.34539 ISENTO (JOSÉ Jr) - JARAGUÁ // | B18: MUD END + ALT PLAN | D18: VALIDAÇÃO OK ENVIAR AO CADASTRO | E18: 34991737280 | F18: 46116 | G18: =PROPER(TEXT(F18,"DDD")) -> Sáb | H18: 0.33333333 | I18: ISENTO | J18: ENDEREÇO NOVO: RUA ALBERTO TOLEDO BARTON, 70 COMPLEMENTO: CASA UNICA CEP: 38413407 BAIRRO: JARAGUÁ | K18: . <b>ONU = DATA // CONECTOR = VERDE.</b> | L18: =IF(B18="MUD END","NÃO","SIM") -> SIM | M18: PLANO ATUAL: 600 MEGA/79,90 CONTRATADO EM 09/2024 COM FIDELIDADE DE 12 MESES. ROTEADOR: HUAWEI AX2 PLANO OFERTADO: 600 MEGA/79,90. BENEFÍCIOS: ACESSO GRATUITO AO APP MZTV (CDNTV+) | N18: SIM | O18: - | P18: - | Q18: COMPROVANTE DE ENDEREÇO (CEMIG) EM ANEXO NOME NO COMPROVANTE: DOUGLAS CARVALHO DOMINGOS (ESPOSO DA TITULAR) | R18: MK END: IASMYN RODRIGUES CUNHA CPF:705.850.926-30 PROCESSO DE ADESÃO APROVADO NO DIA 12/04/2024 PARA SUA MÃE CRISTIENE SILVA RODRIGUES. CRISTIENE SILVA RODRIGUES CUNHA CPF:912.026.126-87 CONEXÃO CANCELADA POR INADIMPLÊNCIA NO MES 03/2025( DEBITOS R$1706,03) NÃO DEVOLVEU OS EQUIPAMENTOS. MK NOMES: DOUGLAS CARVALHO DOMINGOS CPF 124.7**.***-**(CLIENTE DIZ QUE É SEU ESPOSO)N/C | S18: =IF(F18<TODAY(),"EXECUTADA",IF(F18=TODAY(),"EM EXECUÇÃO",IF(F18=TODAY()+1,"VALIDAR HOJE",IF(F18>TODAY()+1,"VALIDAR DEPOIS","-")))) -> EXECUTADA
A19: MUD END LEANDRO EMANUEL ROSA OLIVEIRA PROT:2603.29238 PIX (BRUNA) - CUSTÓDIO PEREIRA 04/04/2026 ÁS 08HRS // *ANALISE 90 DIAS* | B19: MUD END | D19: ANALISE 90 DIAS TUDO OK .. ENVIAR CADASTRO | E19: 34991194542 | F19: 46116 | G19: =PROPER(TEXT(F19,"DDD")) -> Sáb | H19: 0.33333333 | I19: PIX | J19: ENDEREÇO NOVO: RUA VISCONDE DE OURO PRETO, 115 COMPLEMENTO: CASA FRENTE CEP: 38405202 BAIRRO: CUSTÓDIO PEREIRA | K19: <b>ONT = ONT TP LINK 530 // CONECTOR = VERDE.</b> | L19: =IF(B19="MUD END","NÃO","SIM") -> NÃO | M19: - | N19: NÃO | O19: LUCIANA ROSA DE OLIVIERA (MÃE) | P19: 16981284004 | Q19: COMPROVANTE DE ENDEREÇO (CEMIG) EM ANEXO NOME NO COMPROVANTE: JAMIRO FLORENCIO DOS SANTOS (DIZ SER PROPRIETARIO DO IMOVEL) | R19: MK END: N/C MK NOMES: JAMIRO FLORENCIO DOS SANTOS (PROPRIETARIO): N/C LUCIANA ROSA DE OLIVIERA (MÃE DE LEANDRO): N/C | S19: =IF(F19<TODAY(),"EXECUTADA",IF(F19=TODAY(),"EM EXECUÇÃO",IF(F19=TODAY()+1,"VALIDAR HOJE",IF(F19>TODAY()+1,"VALIDAR DEPOIS","-")))) -> EXECUTADA
A20: MUD END + ALT PLANO ROBSON LIBERIO DA SILVA PROT:2603.34423 ISENTO (HALYSON) - NOSSA SENHORA DAS GRAÇAS // *PEND. COMPROVANTE ENDEREÇO E DE PAGAMENTO* | B20: MUD END + ALT PLAN | D20: VALIDAÇÃO OK ENVIAR AO CADASTRO | E20: 34998824249 | F20: 46116 | G20: =PROPER(TEXT(F20,"DDD")) -> Sáb | H20: 0.41666667 | I20: ISENTO | J20: ENDEREÇO NOVO: RUA CEARÁ, 922 COMPLEMENTO: CASA CEP: 38402018 BAIRRO: NOSSA SENHORA DAS GRAÇAS | K20: <b>ONT = ONT TP LINK 230 // CONECTOR = VERDE.</b> | L20: =IF(B20="MUD END","NÃO","SIM") -> SIM | M20: PLANO ATUAL: 600 MEGA/79,90 CONTRATADO EM 09/2024 COM FIDELIDADE DE 12 MESES. ROTEADOR: ONT TP-LINK XC230 PLANO OFERTADO: 600 MEGA/79,90. BENEFÍCIOS: ACESSO GRATUITO AO APP MZTV (CDNTV+) | N20: SIM | O20: - | P20: - | Q20: COMPROVANTE DE ENDEREÇO (CONTRATO DE LOCAÇÃO) EM ANEXO NOME NO COMPROVANTE: ROBSON LIBERIO DA SILVA (ASSINANTE) | R20: MK NOMES: TATIANE BATISTA MARTINS CORREIA (PROPRIETARIO) - N/C ROBSON LIBERIO DA SILVA (LOCATÁRIO) ASSINANTE, CONEXÃO ATIVA E ADIMPLENTE MK END: N/C | S20: =IF(F20<TODAY(),"EXECUTADA",IF(F20=TODAY(),"EM EXECUÇÃO",IF(F20=TODAY()+1,"VALIDAR HOJE",IF(F20>TODAY()+1,"VALIDAR DEPOIS","-")))) -> EXECUTADA
A21: MUD END VANESSA LISBOA MIRANDA PROT:2603.32068 CARTÃO (LUIS) - CHÁCARAS TUBALINA E QUARTEL **PRÉDIO COM PRUMADA** 04/04/2026 ÁS 10HRS | B21: MUD END | D21: VALIDAÇÃO OK ENVIAR AO CADASTRO | E21: 34991420838 | F21: 46116 | G21: =PROPER(TEXT(F21,"DDD")) -> Sáb | H21: 0.41666667 | I21: cartão | J21: ENDEREÇO NOVO: RUA JOSÉ GARIBALDINO, 350 COMPLEMENTO: TOP LIFE ACAPULCO, BL 18 APT 404 CEP: 38413295 BAIRRO: CHÁCARAS TUBALINA E QUARTEL | K21: <b>ONT = ONT TP LINK 530 // CONECTOR = VERDE.</b> | L21: =IF(B21="MUD END","NÃO","SIM") -> NÃO | M21: - | N21: NÃO | O21: THAUANNY (FILHA DE VANESSA) | P21: (34) 99241-2049 | Q21: COMPROVANTE DE ENDEREÇO (CEMIG) EM ANEXO. NOME NO COMPROVANTE: VITOR FELIPE SOARES FERREIRA (ALEGA SER DONO DA RESIDÊNCIA ) | R21: MK END: N/C MK NOME: - VITOR FELIPE SOARES FERREIRA (ALEGA SER DONO DO IMÓVEL) N/C; - VANESSA LISBOA MIRANDA - CPF: 081.726.936-30- ASSINANTE - CLIENTE ATIVO E ADIMPLENTE COM A EMPRESA | S21: =IF(F21<TODAY(),"EXECUTADA",IF(F21=TODAY(),"EM EXECUÇÃO",IF(F21=TODAY()+1,"VALIDAR HOJE",IF(F21>TODAY()+1,"VALIDAR DEPOIS","-")))) -> EXECUTADA
A22: MUD END + ALT PLANO LUCILIA CANDIDA LIMA SOBRAL PROT:2604.161 ISENTO (ANDREZA) - CHÁCARAS TUBALINA E QUARTEL **PRÉDIO COM PRUMADA** // *TROCA DE EQUIPAMENTO* | B22: MUD END + ALT PLAN | D22: VALIDAÇÃO OK ENVIAR AO CADASTRO COBRAR ASSINATURA DO CONTRATO | E22: 34920008902 | F22: 46116 | G22: =PROPER(TEXT(F22,"DDD")) -> Sáb | H22: APÓS AS 11:00 | I22: ISENTO | J22: ENDEREÇO NOVO: RUA DIMAS MACHADO, 164 COMPLEMENTO: RESIDENCIAL PALLACE PLANALTO - BLOCO 3, APTO 208 CEP: 38413291 BAIRRO: CHÁCARAS TUBALINA E QUARTEL | K22: <b>ONU = DATA // CONECTOR = VERDE.</b> | L22: =IF(B22="MUD END","NÃO","SIM") -> SIM | M22: PLANO ATUAL: 1000 MEGA/99,90 CONTRATADO EM 01/2024 COM FIDELIDADE DE 12 MESES. ROTEADOR: ZTE H199-A PLANO OFERTADO: 1 GIGA (1.000 MEGA) R$99,90. BENEFÍCIOS: ACESSO GRATUITO AO APP MZTV (CDNTV+) + VOD | N22: SIM | O22: - | P22: - | Q22: COMPROVANTE DE ENDEREÇO (TAXA DE MUDANÇA DE CONDOMÍNIO) EM ANEXO NOME NO COMPROVANTE: ALEXIA CRISTINE DE OLIVEIRA MENDONÇA (DISSE QUE É A DONA DO IMÓVEL) | R22: MK END: N/C ________________________________________ MK NOMES: -> ALEXIA CRISTINE DE OLIVEIRA MENDONÇA (DISSE QUE É A DONA DO IMÓVEL) - CPF 101.272.306-29: N/C | S22: =IF(F22<TODAY(),"EXECUTADA",IF(F22=TODAY(),"EM EXECUÇÃO",IF(F22=TODAY()+1,"VALIDAR HOJE",IF(F22>TODAY()+1,"VALIDAR DEPOIS","-")))) -> EXECUTADA
A23: MUD END + ALT PLANO LARA SILVA CIPRIANO (MARIA/MAE) PROT:2603.35997 ISENTO (LUIS) - LOTEAMENTO PORTAL DO VALE II **PRÉDIO COM PRUMADA** // | B23: MUD END + ALT PLAN | D23: PENDENTE CONFERENCIAS | E23: 34999103758 | F23: 46116 | G23: =PROPER(TEXT(F23,"DDD")) -> Sáb | H23: APÓS AS 11:00 | I23: ISENTO | J23: ENDEREÇO NOVO: RUA REINALDO ALVES DA ROCHA, 850 COMPLEMENTO: COND, VISTA DO VALE 02 BL 02 APT 602 CEP: 38436086 BAIRRO: LOTEAMENTO PORTAL DO VALE II | K23: <b>ONT = ONT TP LINK 230 // CONECTOR = VERDE.</b> | L23: =IF(B23="MUD END","NÃO","SIM") -> SIM | M23: PLANO ATUAL: 600 MEGA/79,90 CONTRATADO EM 12/2024 COM FIDELIDADE DE 12 MESES. ROTEADOR: ONT TP-LINK XC230 PLANO OFERTADO: 600 MEGA/79,90. BENEFÍCIOS: ACESSO GRATUITO AO APP MZTV (CDNTV+) | N23: SIM | O23: - | P23: - | Q23: COMPROVANTE DE ENDEREÇO (CONTRATO DE LOCAÇÃO) EM ANEXO NOME NO COMPROVANTE: LARA SILVA CIPRIANO (ASSINANTE) | R23: MK END: N/C MK NOMES: - KEVIN CARVALHO DE CASTRO CPF: 129.955.526-83 - LOCADOR - N/C - LARA SILVA CIPRIANO (MARIA/MAE) - CPF: 884.659.422-34 - LOCATÁRIA (ASSINANTE) CLIENTE ATIVA E ADIMPLENTE COM A EMPRESA. | S23: =IF(F23<TODAY(),"EXECUTADA",IF(F23=TODAY(),"EM EXECUÇÃO",IF(F23=TODAY()+1,"VALIDAR HOJE",IF(F23>TODAY()+1,"VALIDAR DEPOIS","-")))) -> EXECUTADA
A24: MUD END + ALT PLANO EDNEUZA SIQUEIRA LEITE PROT:2604.827 ISENTO (IZABELA) - NOVO MUNDO **PRÉDIO COM PRUMADA** // | B24: MUD END + ALT PLAN | D24: VALIDAÇÃO OK ENVIAR AO CADASTRO PENDENTE ASSINATURA | E24: 34999537343 | F24: 46116 | G24: =PROPER(TEXT(F24,"DDD")) -> Sáb | H24: 0.33333333 | I24: ISENTO | J24: ENDEREÇO NOVO: RUA SANTINA ZANATTA, 103 COMPLEMENTO: AP 307 CEP: 38409047 BAIRRO: NOVO MUNDO | K24: <b>ONT = ONT TP LINK 230 // CONECTOR = VERDE.</b> | L24: =IF(B24="MUD END","NÃO","SIM") -> SIM | M24: PLANO ATUAL: 600 MEGA/79,90 CONTRATADO EM 06/2025 COM FIDELIDADE DE 12 MESES. ROTEADOR: ONT TP-LINK XC230 PLANO OFERTADO: 600 MEGA/79,90. BENEFÍCIOS: ACESSO GRATUITO AO APP MZTV (CDNTV+) | N24: SIM | O24: IRINEU (FILHO DE EDNEUZA) | P24: 19981470830 | Q24: COMPROVANTE DE ENDEREÇO (CONTRATO DE COMPRA E VENDA) EM ANEXO NOME NO COMPROVANTE: IRINEU SIQUEIRA LEITE (FILHO DE EDNEUZA) | R24: MK END - N/C MK NOMES: VINICIUS CARNEIRO DIAS (VENDEDOR) - N/C IRINEU SIQUEIRA LEITE (COMPRADOR / FILHO DA TITULAR) - N/C ____________________________________________________________ REPRESENTANTES ITAÚ UNIBANCO S.A: ANDRE BERANGER VIEIRA (297.484.678-56) - N/C CIRLENE ALVES DOS SANTOS (360.348.728-12) - N/C KELLY CRISTINA KRAUT DE ALMEIDA (260.214.648-00) - N/C LAIS SANTANA GONCALVES DA SILVA (421.336.208-69) - N/C MARIA ELISA MORI (092.650.258-16) - N/C NATALIA DA COSTA ARAUJO (444.426.928-66) - N/C RANULFO DA ROCHA SILVA (222.833.068-09) - N/C RAPHAEL GERMANO AMARO DA SILVA (399.010.958-83) - N/C VANESSA MODESTO DE ABREU (383.100.548-66) - N/C WESLLEY DA SILVA RAMOS DO NASCIMENTO (344.258.558-92) - N/C ANDERSON HENRIQUE TEIXEIRA NOGUEIRA (NÃO HÁ ESPECIFICAÇÃO DA OCUPAÇÃO DO MESMO) - N/C BARBARA APARECIDA OTONI (NÃO HÁ ESPECIFICAÇÃO DA OCUPAÇÃO DA MESMA) - N/C | S24: =IF(F24<TODAY(),"EXECUTADA",IF(F24=TODAY(),"EM EXECUÇÃO",IF(F24=TODAY()+1,"VALIDAR HOJE",IF(F24>TODAY()+1,"VALIDAR DEPOIS","-")))) -> EXECUTADA
A25: MUD END KLEVERSON ERRERA DE SOUZA PROT:2604.1722 PIX (ANDREZA) - SANTA MÔNICA | B25: MUD END + ALT PLAN | D25: VALIDAÇÃO OK ENVIAR AO CADASTRO | E25: 17997351940 | F25: 46116 | G25: =PROPER(TEXT(F25,"DDD")) -> Sáb | H25: APÓS AS 11:00 HORAS | I25: PIX | J25: ENDEREÇO NOVO: AVENIDA ORTÍZIO BORGES, 1398 COMPLEMENTO: CASA FUNDO CEP: 38408263 BAIRRO: SANTA MÔNICA | K25: <b>ONT = ONT ZTE // CONECTOR = VERDE.</b> | L25: =IF(B25="MUD END","NÃO","SIM") -> SIM | M25: PLANO ATUAL: 600 MEGA/79,90 CONTRATADO EM 04/2025 COM FIDELIDADE DE 12 MESES. ROTEADOR: ONT ZTE F 670-L PLANO OFERTADO: 600 MEGA/79,90. BENEFÍCIOS: ACESSO GRATUITO AO APP MZTV (CDNTV+) | N25: SIM | O25: - | P25: - | Q25: COMPROVANTE DE ENDEREÇO (CONTRATO DE LOCAÇÃO) EM ANEXO NOME NO COMPROVANTE: KLEVERSON ERRERA DE SOUZA (ASSINANTE) | R25: MK END: N/C ________________________________________ MK NOMES: -> ANTONIO PEREIRA TOSTA (LOCADOR) - CPF 103.551.891-00: N/C -> KLEVERSON ERRERA DE SOUZA (LOCATÁRIO) - CPF 102.820.168-05: ASSINANTE DA CONEXÃO. -> SANDRA ELISA CASALE (ESPOSA DO LOCATÁRIO) - CPF 102.852.798-58: N/C | S25: =IF(F25<TODAY(),"EXECUTADA",IF(F25=TODAY(),"EM EXECUÇÃO",IF(F25=TODAY()+1,"VALIDAR HOJE",IF(F25>TODAY()+1,"VALIDAR DEPOIS","-")))) -> EXECUTADA
A26: MUD END WESLEY DE SOUZA GONCALVES PROT:2603.32228 PIX (VAGNER) - SÃO JORGE // *ANALISE* | B26: MUD END | D26: -PENDENTE COMPROVANTE - ENDEREÇO NÃO ALTERADO - MENSALIDADE PENDENTE - ANÁLISE 90 DIAS | E26: 34997153668 | F26: 46116 | G26: =PROPER(TEXT(F26,"DDD")) -> Sáb | H26: APÓS AS 11:00 | I26: PIX | J26: ENDEREÇO NOVO: AVENIDA SERRA DO ESPINHAÇO, 775 COMPLEMENTO: CASA UNICA CEP: 38410384 BAIRRO: SÃO JORGE | K26: <b>ONU = DATA // CONECTOR = VERDE.</b> | L26: =IF(B26="MUD END","NÃO","SIM") -> NÃO | M26: - | N26: SIM | O26: - | P26: - | Q26: PENDENTE COMPROVANTE | S26: =IF(F26<TODAY(),"EXECUTADA",IF(F26=TODAY(),"EM EXECUÇÃO",IF(F26=TODAY()+1,"VALIDAR HOJE",IF(F26>TODAY()+1,"VALIDAR DEPOIS","-")))) -> EXECUTADA
A27: RESERVA RONALD / MUD END / JUVENIL MARIO BENEDITO | B27: MUD END + ALT PLAN | D27: -Pendente comprovante atualizado - Complemento, melhorar informação. descrito como "casa ao lado" - Contrato nao assinado | E27: 34992807809 | F27: 46116 | G27: =PROPER(TEXT(F27,"DDD")) -> Sáb | H27: Após as 11:00 horas | I27: ISENTO | J27: ENDEREÇO NOVO: RUA NATALINA DE CASTRO PEREIRA, 15 COMPLEMENTO: CASA AO LADO CEP: 38401116 BAIRRO: PRESIDENTE ROOSEVELT | K27: <b>ONT = ONT TP LINK 220 // CONECTOR = VERDE.</b> | L27: =IF(B27="MUD END","NÃO","SIM") -> SIM | M27: PLANO ATUAL: 150 MEGA/59,90 CONTRATADO EM 06/2025 COM FIDELIDADE DE 12 MESES. ROTEADOR: ONT TP-LINK XC220 PLANO OFERTADO: 150 MEGA/59,90. BENEFÍCIOS: ACESSO GRATUITO AO APP MZTV (CDNTV+) | N27: SIM | O27: - | P27: - | Q27: PENDENTE COMPROVANTE | S27: =IF(F27<TODAY(),"EXECUTADA",IF(F27=TODAY(),"EM EXECUÇÃO",IF(F27=TODAY()+1,"VALIDAR HOJE",IF(F27>TODAY()+1,"VALIDAR DEPOIS","-")))) -> EXECUTADA
A28: MUD END NAIANE RODRIGUES DE SOUSA MELO PROT:2603.34560 PIX (BRUNA) - SEGISMUNDO PEREIRA // | B28: MUD END | D28: VALIDAÇÃO OK ENVIAR AO CADASTRO | E28: 34997684409 | F28: 46118 | G28: =PROPER(TEXT(F28,"DDD")) -> Seg | H28: 0.625 | I28: PIX | J28: ENDEREÇO NOVO: RUA JOÃO ÂNGELO SCHIAVINATO, 1613 COMPLEMENTO: CASA ÚNICA CEP: 38408272 BAIRRO: SEGISMUNDO PEREIRA | K28: <b>ONT = ONT TP LINK 530 // CONECTOR = VERDE.</b> | L28: =IF(B28="MUD END","NÃO","SIM") -> NÃO | M28: - | N28: NÃO | O28: CLAITON DE OLIVEIRA MELO (ESPOSO) | P28: 34 9128-6717 | Q28: COMPROVANTE DE ENDEREÇO (CONTRATO DE LOCAÇÃO) EM ANEXO NOME NO COMPROVANTE: NAIANE RODRIGUES DE SOUSA MELO (ASSINANTE) | R28: MK END: N/C MK NOMES: VANDA LEONARDO ALVES FREITAS (LOCADORA):N/C NAIANE RODRIGUES DE SOUSA MELO (LOCATÁRIA/ASSINANTE): CONEXÃO ATIVA E SEM PENDENCIAS. CLAITON DE OLIVEIRA MELO (LOCATÁRIO/ESPOSO DE NAIANE):N/C CREUZA MARIA DE OLIVEIRA MELO (FIADORA):N/C CEMIG (CONCESSIONÁRIA):N/C BANCO BRADESCO (INSTITUIÇÃO FINANCEIRA):N/C | S28: =IF(F28<TODAY(),"EXECUTADA",IF(F28=TODAY(),"EM EXECUÇÃO",IF(F28=TODAY()+1,"VALIDAR HOJE",IF(F28>TODAY()+1,"VALIDAR DEPOIS","-")))) -> EXECUTADA
A29: MUD END PIETRO URBANO GALVAO PROT:2603.35889 PIX (JHONATAN) - **PRÉDIO SEM PRUMADA - ENVIAR TÉCNICO DUPLADO** *AGUARDANDO ANALISE PRÉDIO (VERTICAL)* | B29: MUD END | D29: VALIDAÇÃO OK ENVIAR AO CADASTRO | E29: 34999529448 | F29: 46118 | G29: =PROPER(TEXT(F29,"DDD")) -> Seg | H29: 0.54166667 | I29: PIX | J29: ENDEREÇO NOVO: RUA TUPACIGUARA, 400 COMPLEMENTO: AP 401 CEP: 38400618 BAIRRO: NOSSA SENHORA APARECIDA | K29: <b>ONT = ONT TP LINK 530 // CONECTOR = VERDE.</b> | L29: =IF(B29="MUD END","NÃO","SIM") -> NÃO | M29: - | N29: SIM | O29: - | P29: - | Q29: COMPROVANTE DE ENDEREÇO (DMAE) EM ANEXO NOME NO COMPROVANTE: PIETRO URBANO GALVÃO (ASSINANTE) | R29: MK END N/C MK NOMES -> PIETRO URBANO GALVÃO (LOCATÁRIO / ASSINANTE DA CONEXÃO) -> VALDEMAR DA SILVA ZUZA (LOCADOR / PROPRIETÁRIO DO IMÓVEL): N/C -> MÁRCIO ANDRÉ GUIMARÃES GALVÃO (FIADOR): POSSUI CONEXÃO ATIVA E ADIMPLENTE -> TIZIANA ADRIANA URBANO (CÔNJUGE DO FIADOR / FIADORA): N/C -> OBJETIVA IMÓVEIS S/S LTDA (IMOBILIÁRIA): N/C | S29: =IF(F29<TODAY(),"EXECUTADA",IF(F29=TODAY(),"EM EXECUÇÃO",IF(F29=TODAY()+1,"VALIDAR HOJE",IF(F29>TODAY()+1,"VALIDAR DEPOIS","-")))) -> EXECUTADA
A30: MUD END ERIKA CRISTINA ALESSI (ATELIE DE ALTA COSTURA) PROT:2604.1333 PIX (VICTOR H.) - OSVALDO REZENDE // PENDENTE COMPROVANTE DE ENDEREÇO | B30: MUD END | D30: PENDENTE COMPROVANTE | E30: 34991195973 | F30: 46118 | G30: =PROPER(TEXT(F30,"DDD")) -> Seg | I30: PIX | J30: ENDEREÇO NOVO: RUA FRANCISCO SALES, 1140 COMPLEMENTO: COMERCIO CEP: 38400440 BAIRRO: OSVALDO REZENDE | K30: <b>ONT = ONT ZTE // CONECTOR = VERDE.</b> | L30: =IF(B30="MUD END","NÃO","SIM") -> NÃO | M30: - | N30: SIM | O30: - | P30: - | Q30: COMPROVANTE DE ENDEREÇO (DMAE) EM ANEXO NOME NO COMPROVANTE: SONIA MARIA BORBA (DISSE SER IRMÃ DO PROPRIETÁRIO DO IMÓVEL) | R30: MK END: N/C MK NOMES: SONIA MARIA BORBA (DISSE SER IRMÃ DO PROPRIETÁRIO DO IMÓVEL) N/C | S30: =IF(F30<TODAY(),"EXECUTADA",IF(F30=TODAY(),"EM EXECUÇÃO",IF(F30=TODAY()+1,"VALIDAR HOJE",IF(F30>TODAY()+1,"VALIDAR DEPOIS","-")))) -> EXECUTADA
A31: mud end IRIS DE FATIMA MARCELINO CAMARA prot (Victor) | B31: MUD END | D31: VALIDAÇÃO OK ENVIAR AO CADASTRO | E31: 34999811485 | F31: 46118 | G31: =PROPER(TEXT(F31,"DDD")) -> Seg | H31: 0.41666667 | I31: ISENTO | J31: ENDEREÇO NOVO: RUA NICARÁGUA, 794 COMPLEMENTO: APTO 102 CEP: 38405100 BAIRRO: TIBERY | K31: <b>ONT = ONT TP LINK 230 // CONECTOR = VERDE.</b> | L31: =IF(B31="MUD END","NÃO","SIM") -> NÃO | M31: PLANO ATUAL: 1000 MEGA/99,90 CONTRATADO EM 05/2024 COM FIDELIDADE DE 12 MESES. ROTEADOR: ONT TP-LINK XC230 PLANO OFERTADO: 1 GIGA (1.000 MEGA) R$99,90. BENEFÍCIOS: ACESSO GRATUITO AO APP MZTV (CDNTV+) + VOD | N31: SIM | O31: - | P31: - | Q31: COMPROVANTE DE ENDEREÇO (CONTRATO DE LOCAÇÃO) EM ANEXO NOME NO COMPROVANTE: IRIS DE FATIMA MARCELINO CAMARA (ASSINANTE) | R31: MK NOMES: ELCI LOURENÇO BORGES CPF 456.253.446-04 (LOCADOR) N/C MATILDE ALVES BORGES CPF 260.176.956-49 (LOCADORA) N/C IRIS DE FÁTIMA MARCELINO CAMARA RG 143.693.111-87 (LOCATÁRIA) ASSINANTE, CONTRATOU EM 05/2024 CONEXÃO ATIVA E ADIMPLENTE CARLA MARCELINO CÂMARA RG 054.957.476-67 (TESTEMUNHA) N/C MK END: N/C | S31: =IF(F31<TODAY(),"EXECUTADA",IF(F31=TODAY(),"EM EXECUÇÃO",IF(F31=TODAY()+1,"VALIDAR HOJE",IF(F31>TODAY()+1,"VALIDAR DEPOIS","-")))) -> EXECUTADA
A32: MUD END + ALT PLANO LUCAS FERREIRA GOMES PROT:2603.34716 ISENTO (JHONATAN) - DANIEL FONSECA | | B32: MUD END + ALT PLAN | D32: JA VALIDADO ANTERIORMENTE | E32: 34991631067 | F32: 46118 | G32: =PROPER(TEXT(F32,"DDD")) -> Seg | H32: 0.54166667 | I32: ISENTO | J32: ENDEREÇO NOVO: RUA VARGINHA, 1155 COMPLEMENTO: COND. MARANATA, APT 203 CEP: 38400322 BAIRRO: DANIEL FONSECA | K32: . <b>ONT = ONT ZTE // CONECTOR = VERDE.</b> | L32: =IF(B32="MUD END","NÃO","SIM") -> SIM | M32: PLANO ATUAL: 1000 MEGA/99,90 CONTRATADO EM 07/2025 COM FIDELIDADE DE 12 MESES. ROTEADOR: ONT ZTE F 670-L PLANO SOLICITADO: 1 GIGA (1.000 MEGA) R$99,90. BENEFÍCIOS: ACESSO GRATUITO AO APP MZTV (CDNTV+) + VOD | N32: NÃO | O32: DOUGLAS FERNANDES BORGES. (INQUILINO) | P32: 64 9328-2617 | Q32: COMPROVANTE DE ENDEREÇO (CONTRATO DE LOCAÇÃO) EM ANEXO NOME NO COMPROVANTE: DOUGLAS FERNANDES BORGES (INQUILINO) | R32: MK END: N/C ___________________________ MK NOMES: -> SOCRATES RODRIGUES QUEIROZ - CPF: 052.678.796-14 - LOCADOR DO IMÓVEL - CLIENTE ATIVO NO ENDEREÇO: RUA SEBASTIAO DE FREITAS, 287. ADIMPLENTE COM EMPRESA; -> POLIANA EVANGELISTA SILVA - CPF: 059.825.136-79 - LOCATÁRIA DO IMÓVEL - N/C ; -> DOUGLAS FERNANDES BORGES - CPF: 056.809.281-26 - LOCATÁRIO DO IMÓVEL - N/C ; -> LUCAS FERREIRA GOMES - CPF: 065.584.586-08 - CLIENTE ATIVO E ADIMPLENTE COM A EMPRESA. | S32: =IF(F32<TODAY(),"EXECUTADA",IF(F32=TODAY(),"EM EXECUÇÃO",IF(F32=TODAY()+1,"VALIDAR HOJE",IF(F32>TODAY()+1,"VALIDAR DEPOIS","-")))) -> EXECUTADA
A33: MUD END BRENO SANTOS RESENDE PROT:2604.853 PIX (JOSÉ Jr) - PRESIDENTE ROOSEVELT *PENDENTE COMPROVANTE* | B33: MUD END | D33: VALIDAÇÃO OK ENVIAR AO CADASTRO | E33: 34993110530 | F33: 46118 | G33: =PROPER(TEXT(F33,"DDD")) -> Seg | H33: 0.70833333 | I33: PIX | J33: ENDEREÇO NOVO: RUA FERNANDO ALVES VIEIRA, 12 COMPLEMENTO: CASA UNICA CEP: 38401232 BAIRRO: PRESIDENTE ROOSEVELT | K33: <b>ONT = ONT TP LINK 530 // CONECTOR = VERDE.</b> | L33: =IF(B33="MUD END","NÃO","SIM") -> NÃO | M33: - | N33: SIM | O33: - | P33: - | Q33: COMPROVANTE DE ENDEREÇO (CEMIG) EM ANEXO NOME NO COMPROVANTE: DANIEL SOUZA RESENDE (CLIENTE DIZ QUE É O MORADOR ANTIGO) | R33: MK END:N/C NK NOMES: DANIEL SOUZA RESENDE CPF:806.1**.***-**(CLIENTE DIZ QUE É O MORADOR ANTIGO)N/C | S33: =IF(F33<TODAY(),"EXECUTADA",IF(F33=TODAY(),"EM EXECUÇÃO",IF(F33=TODAY()+1,"VALIDAR HOJE",IF(F33>TODAY()+1,"VALIDAR DEPOIS","-")))) -> EXECUTADA
A34: MUD END + ALT PLANO JULIANA GONCALVES BEIJO PROT:2603.33541 ISENTO (VAGNER) - PORTAL DO VALE **PRÉDIO COM PRUMADA** | B34: MUD END + ALT PLAN | D34: VALIDAÇÃO OK ENVIAR AO CADASTRO COBRAR ASSINATURA DO CONTRATO | E34: 34988720868 | F34: 46118 | G34: =PROPER(TEXT(F34,"DDD")) -> Seg | H34: 0.70833333 | I34: ISENTO | J34: ENDEREÇO NOVO: RUA REINALDO ALVES DA ROCHA, 867 COMPLEMENTO: BLOCO 2 AP 1008 CEP: 38436086 BAIRRO: LOTEAMENTO PORTAL DO VALE II | K34: <b>ONT = ONT TP LINK 220 // CONECTOR = VERDE.</b> | L34: =IF(B34="MUD END","NÃO","SIM") -> SIM | M34: PLANO ATUAL: 150 MEGA/59,90 CONTRATADO EM 09/2024 COM FIDELIDADE DE 12 MESES. ROTEADOR: ONT TP-LINK XC220 PLANO OFERTADO: 150 MEGA/59,90. BENEFÍCIOS: ACESSO GRATUITO AO APP MZTV (CDNTV+) | N34: SIM | O34: - | P34: - | Q34: COMPROVANTE DE ENDEREÇO (DMAE) EM ANEXO NOME NO COMPROVANTE: DANIELA DE OLIVEIRA FARINA (DISSE SER ANTIGA PROPRIETÁRIA) | R34: MK END: HUDSON MARQUETE BEIJO (JULIANA DISSE SER SEU CÔNJUGE) – POSSUI UM PEDIDO DE INSTALAÇÃO REALIZADO NO DIA 19/03/2026. AO QUESTIONAR, INFORMOU QUE HUDSON RESIDE COM ELA NO LOCAL E QUE O PEDIDO FOI FEITO ANTES DA DECISÃO ENTRE CONTRATAR UM NOVO PLANO OU SOLICITAR A MUDANÇA. RELATOU AINDA QUE HUDSON IRÁ SOLICITAR O CANCELAMENTO DO PEDIDO DE INSTALAÇÃO. MK NOME: DANIELA DE OLIVEIRA FARINA (DISSE SER ANTIGA PROPRIETÁRIA)- N/C MARCIO ANTONIO DE FREITAS JUNIOR (DISSE SER ANTIGO MORADOR) - N/C | S34: =IF(F34<TODAY(),"EXECUTADA",IF(F34=TODAY(),"EM EXECUÇÃO",IF(F34=TODAY()+1,"VALIDAR HOJE",IF(F34>TODAY()+1,"VALIDAR DEPOIS","-")))) -> EXECUTADA
A35: MUD END + ALT PLANO JULIANA COUTINHO FERREIRA PROT:2603.18313 ISENTO (VICTOR H.) - TOCANTINS // | B35: MUD END + ALT PLAN | C35: mensalidade pendente demais conferencias ok. | E35: 34998613955 | F35: 46118 | G35: =PROPER(TEXT(F35,"DDD")) -> Seg | H35: 0.625 | I35: ISENTO | J35: ENDEREÇO NOVO: RUA APARECIDA DE FÁTIMA CUNHA, 190 COMPLEMENTO: CASA FUNDO CEP: 38415345 BAIRRO: TOCANTINS | K35: <b>ONT = ONT TP LINK 220 // CONECTOR = VERDE.</b> | L35: =IF(B35="MUD END","NÃO","SIM") -> SIM | M35: PLANO ATUAL: 150 MEGA/59,90 CONTRATADO EM 04/2025 COM FIDELIDADE DE 12 MESES. ROTEADOR: ONT TP-LINK XC220 PLANO OFERTADO: 150 MEGA/59,90. BENEFÍCIOS: ACESSO GRATUITO AO APP MZTV (CDNTV+) | N35: SIM | O35: - | P35: - | Q35: COMPROVANTE DE ENDEREÇO (CEMIG) EM ANEXO NOME NO COMPROVANTE: JULIANA COUTINHO FERREIRA (ASSINANTE) | R35: MK END: - ANA VITORIA PEREIRA CAMPOS - CPF: 043.955.962-66 - FICHA CADASTRAL REALIZADA EM 11/2022 NA QUAL FOI REPROVADA; - WANISLAYLA FERNANDA DA COSTA - CPF: 112.169.146-30 - CONEXÃO ATIVA NO MESMO ENDEREÇO ENTRETANTO COMPLEMENTO É CASA FRENTE. CLIENTE ATIVA E ADIMPLENTE COM A EMPRESA. MK NOMES: - JULIANA COUTINHO FERREIRA - CPF: 705.333.442-20 - ASSINANTE - CLIENTE ATIVA E ADIMPLENTE COM A EMPRESA. | S35: =IF(F35<TODAY(),"EXECUTADA",IF(F35=TODAY(),"EM EXECUÇÃO",IF(F35=TODAY()+1,"VALIDAR HOJE",IF(F35>TODAY()+1,"VALIDAR DEPOIS","-")))) -> EXECUTADA
A36: MUD END + ALT PLANO KENIA CRISTINA AQUINO CARVALHO PROT:2603.34621 ISENTO (HALYSON) - PRESIDENTE ROOSEVELT // *PEND. COMPROVANTE ENDEREÇO* | B36: MUD END + ALT PLAN | D36: PENDENTE COMPROVANTE SEM OS GERADA | E36: 34998954165 | F36: 46118 | G36: =PROPER(TEXT(F36,"DDD")) -> Seg | H36: 0.41666667 | I36: ISENTO | J36: ENDEREÇO NOVO: AVENIDA ADRIANO BAILONI, 64 COMPLEMENTO: SOBRADO CEP: 38401092 BAIRRO: PRESIDENTE ROOSEVELT | L36: =IF(B36="MUD END","NÃO","SIM") -> SIM | M36: PLANO ATUAL: 1000 MEGA/99,90 CONTRATADO EM 02/2025 COM FIDELIDADE DE 12 MESES. ROTEADOR: ONT TP-LINK X530 PLANO OFERTADO: 1 GIGA (1.000 MEGA) R$99,90. BENEFÍCIOS: ACESSO GRATUITO AO APP MZTV (CDNTV+) + VOD | Q36: PENDENTE COMPROVANTE | S36: =IF(F36<TODAY(),"EXECUTADA",IF(F36=TODAY(),"EM EXECUÇÃO",IF(F36=TODAY()+1,"VALIDAR HOJE",IF(F36>TODAY()+1,"VALIDAR DEPOIS","-")))) -> EXECUTADA
A37: MUD END ELEUBER DOS SANTOS PROT:2604.302 DINHEIRO (BRUNA) - JARDIM PATRÍCIA // *PEND COMPROVANTE DE END* *PEND VALIDAÇÃO DO TITULAR* | B37: MUD END | D37: PENDENTE COMPROVANTE | E37: 34996862353 | F37: 46118 | G37: =PROPER(TEXT(F37,"DDD")) -> Seg | I37: DINHEIRO | J37: ENDEREÇO NOVO: RUA ARDÓSIA, 52 COMPLEMENTO: CASA FRENTE CEP: 38414136 BAIRRO: JARDIM PATRÍCIA | K37: <b>ONT = ONT TP LINK 220 // CONECTOR = VERDE.</b> | L37: =IF(B37="MUD END","NÃO","SIM") -> NÃO | M37: - | N37: SIM | O37: EVA (ESPOSA DE ELEUBER) | P37: 3498407-2244 | S37: =IF(F37<TODAY(),"EXECUTADA",IF(F37=TODAY(),"EM EXECUÇÃO",IF(F37=TODAY()+1,"VALIDAR HOJE",IF(F37>TODAY()+1,"VALIDAR DEPOIS","-")))) -> EXECUTADA
A38: MUD END + ALT PLANO KEVIN XAVIER RIBEIRO PROT:2603.34547 ISENTO (LUIS) - SEGISMUNDO PEREIRA **PRÉDIO COM PRUMADA** // | B38: MUD END + ALT PLAN | D38: PENDENTE APENAS CONFERENCIAS | E38: 34992870010 | F38: 46118 | G38: =PROPER(TEXT(F38,"DDD")) -> Seg | H38: 0.41666667 | I38: ISENTO | J38: ENDEREÇO NOVO: RUA JOÃO BALBINO, 1833 COMPLEMENTO: CONDOMINIO METROPOLI 2 BL D APT 203 CEP: 38408265 BAIRRO: SEGISMUNDO PEREIRA | K38: . <b>ONT = ONT ZTE // CONECTOR = VERDE.</b> | L38: =IF(B38="MUD END","NÃO","SIM") -> SIM | M38: PLANO ATUAL: 500 MEGA/79,90 CONTRATADO EM 04/2024 COM FIDELIDADE DE 12 MESES. ROTEADOR: ONT ZTE F 670-L PLANO OFERTADO: 600 MEGA/79,90. BENEFÍCIOS: ACESSO GRATUITO AO APP MZTV (CDNTV+) | N38: SIM | O38: - | P38: - | Q38: COMPROVANTE DE ENDEREÇO (CONTRATO DE LOCAÇÃO) EM ANEXO NOME NO COMPROVANTE: FLÁVIA LAYLA ALVES AMERICANO (KEVIN ALEGA SER SUA ESPOSA) | R38: MK END: POSSUI UMA FICHA CADASTRAL REALIZADA NO DIA 30/03/2026 NO NOME DE FLAVIA LAYLA ALVES AMERICANO (KEVIN ALEGA SER SUA ESPOSA). MK NOMES: - ANA PAULA PEREIRA DA SILVA – CPF: 866.464.196-04 – LOCADORA - CONEXÃO CANCELADA EM 11/2023 NO ENDEREÇO RUA ALABASTRO, 166. EQUIPAMENTOS FORAM DEVOLVIDOS E SEM DÉBITO EM ABERTO. - SILONE FERREIRA DA SILVA – CPF: 772.001.101-59 – LOCADORA - N/C - FLÁVIA LAYLA ALVES AMERICANO – CPF: 082.496.186-29 – LOCATÁRIA - FOI REALIZADO A FICHA CADASTRAL NA DATA 30/03/2026 PARA O MESMO ENDEREÇO QUE KEVIN ESTÁ SE MUDANDO: RUA JOAO BALBINO, 1833 - BL.D, APT.203 - KEVIN XAVIER RIBEIRO - CPF: 121.764.336-29 - TESTEMUNHA (ASSINANTE) - CLIENTE ATIVO E ADIMPLENTE COM A EMPRESA. | S38: =IF(F38<TODAY(),"EXECUTADA",IF(F38=TODAY(),"EM EXECUÇÃO",IF(F38=TODAY()+1,"VALIDAR HOJE",IF(F38>TODAY()+1,"VALIDAR DEPOIS","-")))) -> EXECUTADA
A39: MUD END CARLOS HAILTON MUNIZ FERREIRA PROT:2603.34987 DINHEIRO (RONALD) - MORUMBI | B39: MUD END | D39: ENDEREÇO NAO ALTERADO NA OS CORRIGIR PROTOCOLO + OS: MUDANÇA AGENDADA PARA DIA 07/04/2026 ÀS 10:00 HRS. COBRAR COMPROVANTE PAGAMENTO REAGENDADO | E39: 34996941853 | F39: 46119 | G39: =PROPER(TEXT(F39,"DDD")) -> Ter | H39: 0.33333333 | I39: DINHEIRO | J39: ENDEREÇO NOVO: RUA ARRUDA, 203 COMPLEMENTO: CASA ÚNICA CEP: 38407129 BAIRRO: MORUMBI | K39: <b>ONU = DATA // CONECTOR = VERDE.</b> | L39: =IF(B39="MUD END","NÃO","SIM") -> NÃO | M39: - | N39: SIM | O39: - | P39: - | Q39: COMPROVANTE DE ENDEREÇO (CEMIG) EM ANEXO NOME NO COMPROVANTE: MARIA APARECIDA DA SILVA (ANTIGA INQUILINA) | R39: MK END; JHOATAN JUNIO RODRIGUES LIMA SOLICITOU CONTRATAÇÃO EM 04/2025 PORÉM NÃO FOI APROVADO COM INSTALAÇÃO GRATUITA, PORÉM NÃO TEVE INTERESSE. MK NOME; CARLOS HAILTON MUNIZ FERREIRA (ASSINANTE) CONEXÃO ATIVA E CLIENTE ADIMPLENTE MARIA APARECIDA DA SILVA 366.4**.***-** (ANTIGA INQUILINA) N/C | S39: =IF(F39<TODAY(),"EXECUTADA",IF(F39=TODAY(),"EM EXECUÇÃO",IF(F39=TODAY()+1,"VALIDAR HOJE",IF(F39>TODAY()+1,"VALIDAR DEPOIS","-")))) -> EXECUTADA
A40: MUD END IVALDA PEREIRA DA SILVA PROT: 2603.35714 DINHEIRO (HALYSON) - TIBERY | B40: MUD END | D40: VALIDAÇÃO OK ENVIAR AO CADASTRO | E40: 34999773460 | F40: 46119 | G40: =PROPER(TEXT(F40,"DDD")) -> Ter | H40: 0.33333333 | I40: DINHEIRO | J40: ENDEREÇO NOVO: RUA GRÉCIA, 429 COMPLEMENTO: CASA 3 CEP: 38405064 BAIRRO: TIBERY | K40: <b>ONT = ONT TP LINK 220 // CONECTOR = VERDE.</b> | L40: =IF(B40="MUD END","NÃO","SIM") -> NÃO | M40: - | N40: SIM | O40: SIDNEY (ESPOSO DE IVALDA) | P40: 34996945543 | Q40: COMPROVANTE DE ENDEREÇO (DMAE) EM ANEXO NOME NO COMPROVANTE: VAIDE VENANCIO DA SILVA (PAI DA ASSINANTE) | R40: MK END: N/C MK NOMES - VAIDE VENANCIO DA SILVA (PROPRIETÁRIO E PAI DA ASSINANTE): N/C - IVALDA PEREIRA DA SILVA (ASSINANTE): POSSUI CONEXÃO ATIVA E ADIMPLENTE. - SIDNEI ROBERTO GOULART DOS SANTOS (ESPOSO DA ASSINANTE): PEDIDO DE ADESÃO APROVADO PARA ESPOSA *IVALDA PEREIRA DA SILVA 16/05/2025 | S40: =IF(F40<TODAY(),"EXECUTADA",IF(F40=TODAY(),"EM EXECUÇÃO",IF(F40=TODAY()+1,"VALIDAR HOJE",IF(F40>TODAY()+1,"VALIDAR DEPOIS","-")))) -> EXECUTADA
...
